Workbook
Name Orders: Orders!$A$1:$U$9995
Name People: People!$A$1:$B$5
Name Returns: Returns!#REF!
Name Срез_Category: #N/A
Name Срез_Order_Date: #N/A
Name Срез_Region: #N/A
Name Срез_Segment1: #N/A
Name Срез_Годы: #N/A

Sheet Main list
A1: SUPERSTORE SAMPLE DASHBOARD
A34: by category
A52: by segments

Sheet Income and profit dynamics
B3: Данные
A4: Названия строк | B4: Сумма по полю Sales | C4: Сумма по полю Profit
A5: янв | B5: 94924.836 | C5: 9134.4461
A6: фев | B6: 59751.251 | C6: 10294.611
A7: мар | B7: 205005.49 | C7: 28594.687
A8: апр | B8: 137762.13 | C8: 11587.436
A9: май | B9: 155028.81 | C9: 22411.308
A10: июн | B10: 152718.68 | C10: 21285.795
A11: июл | B11: 147238.1 | C11: 13832.665
A12: авг | B12: 159044.06 | C12: 21776.938
A13: сен | B13: 307649.95 | C13: 36857.475
A14: окт | B14: 200322.98 | C14: 31784.041
A15: ноя | B15: 352461.07 | C15: 35468.426
A16: дек | B16: 325293.5 | C16: 43369.192
A17: Общий итог | B17: 2297200.9 | C17: 286397.02

Sheet Category
C3: Данные
A4: Category | B4: Sub-Category | C4: Сумма по полю Sales | D4: Сумма по полю Profit
A5: Furniture | C5: 741999.8 | D5: 18451.273
A6: Office Supplies | C6: 719047.03 | D6: 122490.8
A7: Technology | C7: 836154.03 | D7: 145454.95
A8: Общий итог | C8: 2297200.9 | D8: 286397.02

Sheet Regional managers
B3: Данные
A4: Person | B4: Сумма по полю Sales | C4: Сумма по полю Profit
A5: Anna Andreadi | B5: 725457.82 | C5: 108418.45
A6: Cassandra Brandow | B6: 391721.91 | C6: 46749.43
A7: Chuck Magee | B7: 678781.24 | C7: 91522.78
A8: Kelly Williams | B8: 501239.89 | C8: 39706.362
A9: Общий итог | B9: 2297200.9 | C9: 286397.02

Sheet Segments
B3: Данные
A4: Segment | B4: Сумма по полю Sales | C4: Сумма по полю Profit
A5: Consumer | B5: 1161401.3 | C5: 134119.21
A6: Corporate | B6: 706146.37 | C6: 91979.134
A7: Home Office | B7: 429653.15 | C7: 60298.679
A8: Общий итог | B8: 2297200.9 | C8: 286397.02

Sheet Sales dynamics by segment
A3: Сумма по полю Profit | C3: Segment
A4: Годы | B4: Order Date | C4: Consumer | D4: Corporate | E4: Home Office
A5: 2016
B6: мар | C6: 597.2773 | D6: 333.0515 | E6: -431.5989
A7: 2017 | C7: 5338.1773 | D7: 3886.7496 | E7: 507.1709
A8: 2018 | C8: 2468.6651 | D8: -327.4601 | E8: 1470.763
A9: 2019 | C9: 9682.0015 | D9: 3911.9128 | E9: 1157.9772

Sheet Map Pivot
A2: United States | B2: Alabama | C2: 256
B3: Arizona | C3: 862
B4: Arkansas | C4: 240
B5: California | C5: 7667
B6: Colorado | C6: 693
B7: Connecticut | C7: 281
B8: Delaware | C8: 367
B9: District of Columbia | C9: 40
B10: Florida | C10: 1379
B11: Georgia | C11: 705
B12: Idaho | C12: 64
B13: Illinois | C13: 1845
B14: Indiana | C14: 578
... B50: Wyoming | C50: 4
A51: United States Итог | C51: 37873
A52: Общий итог | C52: 37873

Sheet Regions
A3: Сумма по полю Quantity
A4: Region | B4: Итог
A5: Central | B5: 0.23182742
A6: East | B6: 0.28035804
A7: South | B7: 0.16394265
A8: West | B8: 0.32387189
A9: Общий итог | B9: 1

Sheet Orders
A1: Row ID | B1: Order ID | C1: Order Date | D1: Ship Date | E1: Ship Mode | F1: Customer ID | G1: Customer Name | H1: Segment | I1: Country | J1: City | K1: State | L1: Postal Code | M1: Region | N1: Product ID | O1: Category | P1: Sub-Category | Q1: Product Name | R1: Sales | S1: Quantity | T1: Discount | U1: Profit | V1: Person | W1: Returned
A2: 1 | B2: CA-2018-152156 | C2: 2018-11-08 | D2: 2018-11-11 | E2: Second Class | F2: CG-12520 | G2: Claire Gute | H2: Consumer | I2: United States | J2: Henderson | K2: Kentucky | L2: 42420 | M2: South | N2: FUR-BO-10001798 | O2: Furniture | P2: Bookcases | Q2: Bush Somerset Collection Bookcase | R2: 261.96 | S2: 2 | T2: 0 | U2: 41.9136 | V2: =IF(M2=People!$B$5,People!$A$5,IF(M2=People!$B$2,People!$A$2,IF(M2=People!$B$3,People!$A$3,IF(M2=People!$B$4,People!$A$4,)))) -> Cassandra Brandow | W2: =IFERROR(VLOOKUP(B2,Returns!$A$2:$C$801,2,1), "No") -> Yes
A3: 2 | B3: CA-2018-152156 | C3: 2018-11-08 | D3: 2018-11-11 | E3: Second Class | F3: CG-12520 | G3: Claire Gute | H3: Consumer | I3: United States | J3: Henderson | K3: Kentucky | L3: 42420 | M3: South | N3: FUR-CH-10000454 | O3: Furniture | P3: Chairs | Q3: Hon Deluxe Fabric Upholstered Stacking Chairs, Rounded Back | R3: 731.94 | S3: 3 | T3: 0 | U3: 219.582 | V3: =IF(M3=People!$B$5,People!$A$5,IF(M3=People!$B$2,People!$A$2,IF(M3=People!$B$3,People!$A$3,IF(M3=People!$B$4,People!$A$4,)))) -> Cassandra Brandow | W3: =IFERROR(VLOOKUP(B3,Returns!$A$2:$C$801,2,1), "No") -> Yes
A4: 3 | B4: CA-2018-138688 | C4: 2018-06-12 | D4: 2018-06-16 | E4: Second Class | F4: DV-13045 | G4: Darrin Van Huff | H4: Corporate | I4: United States | J4: Los Angeles | K4: California | L4: 90036 | M4: West | N4: OFF-LA-10000240 | O4: Office Supplies | P4: Labels | Q4: Self-Adhesive Address Labels for Typewriters by Universal | R4: 14.62 | S4: 2 | T4: 0 | U4: 6.8714 | V4: =IF(M4=People!$B$5,People!$A$5,IF(M4=People!$B$2,People!$A$2,IF(M4=People!$B$3,People!$A$3,IF(M4=People!$B$4,People!$A$4,)))) -> Anna Andreadi | W4: =IFERROR(VLOOKUP(B4,Returns!$A$2:$C$801,2,1), "No") -> Yes
A5: 4 | B5: US-2017-108966 | C5: 2017-10-11 | D5: 2017-10-18 | E5: Standard Class | F5: SO-20335 | G5: Sean O'Donnell | H5: Consumer | I5: United States | J5: Fort Lauderdale | K5: Florida | L5: 33311 | M5: South | N5: FUR-TA-10000577 | O5: Furniture | P5: Tables | Q5: Bretford CR4500 Series Slim Rectangular Table | R5: 957.5775 | S5: 5 | T5: 0.45 | U5: -383.031 | V5: =IF(M5=People!$B$5,People!$A$5,IF(M5=People!$B$2,People!$A$2,IF(M5=People!$B$3,People!$A$3,IF(M5=People!$B$4,People!$A$4,)))) -> Cassandra Brandow | W5: =IFERROR(VLOOKUP(B5,Returns!$A$2:$C$801,2,1), "No") -> Yes
A6: 5 | B6: US-2017-108966 | C6: 2017-10-11 | D6: 2017-10-18 | E6: Standard Class | F6: SO-20335 | G6: Sean O'Donnell | H6: Consumer | I6: United States | J6: Fort Lauderdale | K6: Florida | L6: 33311 | M6: South | N6: OFF-ST-10000760 | O6: Office Supplies | P6: Storage | Q6: Eldon Fold 'N Roll Cart System | R6: 22.368 | S6: 2 | T6: 0.2 | U6: 2.5164 | V6: =IF(M6=People!$B$5,People!$A$5,IF(M6=People!$B$2,People!$A$2,IF(M6=People!$B$3,People!$A$3,IF(M6=People!$B$4,People!$A$4,)))) -> Cassandra Brandow | W6: =IFERROR(VLOOKUP(B6,Returns!$A$2:$C$801,2,1), "No") -> Yes
A7: 6 | B7: CA-2016-115812 | C7: 2016-06-09 | D7: 2016-06-14 | E7: Standard Class | F7: BH-11710 | G7: Brosina Hoffman | H7: Consumer | I7: United States | J7: Los Angeles | K7: California | L7: 90032 | M7: West | N7: FUR-FU-10001487 | O7: Furniture | P7: Furnishings | Q7: Eldon Expressions Wood and Plastic Desk Accessories, Cherry Wood | R7: 48.86 | S7: 7 | T7: 0 | U7: 14.1694 | V7: =IF(M7=People!$B$5,People!$A$5,IF(M7=People!$B$2,People!$A$2,IF(M7=People!$B$3,People!$A$3,IF(M7=People!$B$4,People!$A$4,)))) -> Anna Andreadi | W7: =IFERROR(VLOOKUP(B7,Returns!$A$2:$C$801,2,1), "No") -> Yes
A8: 7 | B8: CA-2016-115812 | C8: 2016-06-09 | D8: 2016-06-14 | E8: Standard Class | F8: BH-11710 | G8: Brosina Hoffman | H8: Consumer | I8: United States | J8: Los Angeles | K8: California | L8: 90032 | M8: West | N8: OFF-AR-10002833 | O8: Office Supplies | P8: Art | Q8: Newell 322 | R8: 7.28 | S8: 4 | T8: 0 | U8: 1.9656 | V8: =IF(M8=People!$B$5,People!$A$5,IF(M8=People!$B$2,People!$A$2,IF(M8=People!$B$3,People!$A$3,IF(M8=People!$B$4,People!$A$4,)))) -> Anna Andreadi | W8: =IFERROR(VLOOKUP(B8,Returns!$A$2:$C$801,2,1), "No") -> Yes
A9: 8 | B9: CA-2016-115812 | C9: 2016-06-09 | D9: 2016-06-14 | E9: Standard Class | F9: BH-11710 | G9: Brosina Hoffman | H9: Consumer | I9: United States | J9: Los Angeles | K9: California | L9: 90032 | M9: West | N9: TEC-PH-10002275 | O9: Technology | P9: Phones | Q9: Mitel 5320 IP Phone VoIP phone | R9: 907.152 | S9: 6 | T9: 0.2 | U9: 90.7152 | V9: =IF(M9=People!$B$5,People!$A$5,IF(M9=People!$B$2,People!$A$2,IF(M9=People!$B$3,People!$A$3,IF(M9=People!$B$4,People!$A$4,)))) -> Anna Andreadi | W9: =IFERROR(VLOOKUP(B9,Returns!$A$2:$C$801,2,1), "No") -> Yes
A10: 9 | B10: CA-2016-115812 | C10: 2016-06-09 | D10: 2016-06-14 | E10: Standard Class | F10: BH-11710 | G10: Brosina Hoffman | H10: Consumer | I10: United States | J10: Los Angeles | K10: California | L10: 90032 | M10: West | N10: OFF-BI-10003910 | O10: Office Supplies | P10: Binders | Q10: DXL Angle-View Binders with Locking Rings by Samsill | R10: 18.504 | S10: 3 | T10: 0.2 | U10: 5.7825 | V10: =IF(M10=People!$B$5,People!$A$5,IF(M10=People!$B$2,People!$A$2,IF(M10=People!$B$3,People!$A$3,IF(M10=People!$B$4,People!$A$4,)))) -> Anna Andreadi | W10: =IFERROR(VLOOKUP(B10,Returns!$A$2:$C$801,2,1), "No") -> Yes
A11: 10 | B11: CA-2016-115812 | C11: 2016-06-09 | D11: 2016-06-14 | E11: Standard Class | F11: BH-11710 | G11: Brosina Hoffman | H11: Consumer | I11: United States | J11: Los Angeles | K11: California | L11: 90032 | M11: West | N11: OFF-AP-10002892 | O11: Office Supplies | P11: Appliances | Q11: Belkin F5C206VTEL 6 Outlet Surge | R11: 114.9 | S11: 5 | T11: 0 | U11: 34.47 | V11: =IF(M11=People!$B$5,People!$A$5,IF(M11=People!$B$2,People!$A$2,IF(M11=People!$B$3,People!$A$3,IF(M11=People!$B$4,People!$A$4,)))) -> Anna Andreadi | W11: =IFERROR(VLOOKUP(B11,Returns!$A$2:$C$801,2,1), "No") -> Yes
A12: 11 | B12: CA-2016-115812 | C12: 2016-06-09 | D12: 2016-06-14 | E12: Standard Class | F12: BH-11710 | G12: Brosina Hoffman | H12: Consumer | I12: United States | J12: Los Angeles | K12: California | L12: 90032 | M12: West | N12: FUR-TA-10001539 | O12: Furniture | P12: Tables | Q12: Chromcraft Rectangular Conference Tables | R12: 1706.184 | S12: 9 | T12: 0.2 | U12: 85.3092 | V12: =IF(M12=People!$B$5,People!$A$5,IF(M12=People!$B$2,People!$A$2,IF(M12=People!$B$3,People!$A$3,IF(M12=People!$B$4,People!$A$4,)))) -> Anna Andreadi | W12: =IFERROR(VLOOKUP(B12,Returns!$A$2:$C$801,2,1), "No") -> Yes
A13: 12 | B13: CA-2016-115812 | C13: 2016-06-09 | D13: 2016-06-14 | E13: Standard Class | F13: BH-11710 | G13: Brosina Hoffman | H13: Consumer | I13: United States | J13: Los Angeles | K13: California | L13: 90032 | M13: West | N13: TEC-PH-10002033 | O13: Technology | P13: Phones | Q13: Konftel 250 Conference phone - Charcoal black | R13: 911.424 | S13: 4 | T13: 0.2 | U13: 68.3568 | V13: =IF(M13=People!$B$5,People!$A$5,IF(M13=People!$B$2,People!$A$2,IF(M13=People!$B$3,People!$A$3,IF(M13=People!$B$4,People!$A$4,)))) -> Anna Andreadi | W13: =IFERROR(VLOOKUP(B13,Returns!$A$2:$C$801,2,1), "No") -> Yes
... A2235: 2234 | B2235: CA-2017-123232 | C2235: 2017-12-14 | D2235: 2017-12-16 | E2235: Second Class | F2235: DJ-13630 | G2235: Doug Jacobs | H2235: Consumer | I2235: United States | J2235: Portland | K2235: Oregon | L2235: 97206 | M2235: West | N2235: TEC-PH-10001051 | O2235: Technology | P2235: Phones | Q2235: HTC One | R2235: 319.968 | S2235: 4 | T2235: 0.2 | U2235: 35.9964 | V2235: =IF(M2235=People!$B$5,People!$A$5,IF(M2235=People!$B$2,People!$A$2,IF(M2235=People!$B$3,People!$A$3,IF(M2235=People!$B$4,People!$A$4,)))) -> Anna Andreadi | W2235: =IFERROR(VLOOKUP(B2235,Returns!$A$2:$C$801,2,1), "No") -> Yes
A2236: 2235 | B2236: CA-2019-104066 | C2236: 2019-12-05 | D2236: 2019-12-10 | E2236: Standard Class | F2236: QJ-19255 | G2236: Quincy Jones | H2236: Corporate | I2236: United States | J2236: Burlington | K2236: Vermont | M2236: East | N2236: TEC-AC-10001013 | O2236: Technology | P2236: Accessories | Q2236: Logitech ClearChat Comfort/USB Headset H390 | R2236: 205.03 | S2236: 7 | T2236: 0 | U2236: 67.6599 | V2236: =IF(M2236=People!$B$5,People!$A$5,IF(M2236=People!$B$2,People!$A$2,IF(M2236=People!$B$3,People!$A$3,IF(M2236=People!$B$4,People!$A$4,)))) -> Chuck Magee | W2236: =IFERROR(VLOOKUP(B2236,Returns!$A$2:$C$801,2,1), "No") -> Yes
A2237: 2236 | B2237: CA-2017-145849 | C2237: 2017-09-15 | D2237: 2017-09-17 | E2237: Second Class | F2237: CT-11995 | G2237: Carol Triggs | H2237: Consumer | I2237: United States | J2237: Indianapolis | K2237: Indiana | L2237: 46203 | M2237: Central | N2237: OFF-ST-10000025 | O2237: Office Supplies | P2237: Storage | Q2237: Fellowes Stor/Drawer Steel Plus Storage Drawers | R2237: 190.86 | S2237: 2 | T2237: 0 | U2237: 11.4516 | V2237: =IF(M2237=People!$B$5,People!$A$5,IF(M2237=People!$B$2,People!$A$2,IF(M2237=People!$B$3,People!$A$3,IF(M2237=People!$B$4,People!$A$4,)))) -> Kelly Williams | W2237: =IFERROR(VLOOKUP(B2237,Returns!$A$2:$C$801,2,1), "No") -> Yes
A2238: 2237 | B2238: CA-2017-145849 | C2238: 2017-09-15 | D2238: 2017-09-17 | E2238: Second Class | F2238: CT-11995 | G2238: Carol Triggs | H2238: Consumer | I2238: United States | J2238: Indianapolis | K2238: Indiana | L2238: 46203 | M2238: Central | N2238: OFF-AR-10000817 | O2238: Office Supplies | P2238: Art | Q2238: Manco Dry-Lighter Erasable Highlighter | R2238: 24.32 | S2238: 8 | T2238: 0 | U2238: 8.2688 | V2238: =IF(M2238=People!$B$5,People!$A$5,IF(M2238=People!$B$2,People!$A$2,IF(M2238=People!$B$3,People!$A$3,IF(M2238=People!$B$4,People!$A$4,)))) -> Kelly Williams | W2238: =IFERROR(VLOOKUP(B2238,Returns!$A$2:$C$801,2,1), "No") -> Yes
A2239: 2238 | B2239: CA-2018-122322 | C2239: 2018-07-15 | D2239: 2018-07-21 | E2239: Standard Class | F2239: RH-19510 | G2239: Rick Huthwaite | H2239: Home Office | I2239: United States | J2239: Provo | K2239: Utah | L2239: 84604 | M2239: West | N2239: OFF-SU-10000952 | O2239: Office Supplies | P2239: Supplies | Q2239: Fiskars Home & Office Scissors | R2239: 44.4 | S2239: 5 | T2239: 0 | U2239: 12.432 | V2239: =IF(M2239=People!$B$5,People!$A$5,IF(M2239=People!$B$2,People!$A$2,IF(M2239=People!$B$3,People!$A$3,IF(M2239=People!$B$4,People!$A$4,)))) -> Anna Andreadi | W2239: =IFERROR(VLOOKUP(B2239,Returns!$A$2:$C$801,2,1), "No") -> Yes
A2240: 2239 | B2240: CA-2019-166849 | C2240: 2019-04-20 | D2240: 2019-04-26 | E2240: Standard Class | F2240: SJ-20125 | G2240: Sanjit Jacobs | H2240: Home Office | I2240: United States | J2240: Chicago | K2240: Illinois | L2240: 60610 | M2240: Central | N2240: FUR-FU-10004597 | O2240: Furniture | P2240: Furnishings | Q2240: Eldon Cleatmat Chair Mats for Medium Pile Carpets | R2240: 44.4 | S2240: 2 | T2240: 0.6 | U2240: -52.17 | V2240: =IF(M2240=People!$B$5,People!$A$5,IF(M2240=People!$B$2,People!$A$2,IF(M2240=People!$B$3,People!$A$3,IF(M2240=People!$B$4,People!$A$4,)))) -> Kelly Williams | W2240: =IFERROR(VLOOKUP(B2240,Returns!$A$2:$C$801,2,1), "No") -> Yes
A2241: 2240 | B2241: CA-2018-146633 | C2241: 2018-11-15 | D2241: 2018-11-17 | E2241: Second Class | F2241: TG-21310 | G2241: Toby Gnade | H2241: Consumer | I2241: United States | J2241: Los Angeles | K2241: California | L2241: 90049 | M2241: West | N2241: OFF-BI-10003527 | O2241: Office Supplies | P2241: Binders | Q2241: Fellowes PB500 Electric Punch Plastic Comb Binding Machine with Manual Bind | R2241: 1016.792 | S2241: 1 | T2241: 0.2 | U2241: 381.297 | V2241: =IF(M2241=People!$B$5,People!$A$5,IF(M2241=People!$B$2,People!$A$2,IF(M2241=People!$B$3,People!$A$3,IF(M2241=People!$B$4,People!$A$4,)))) -> Anna Andreadi | W2241: =IFERROR(VLOOKUP(B2241,Returns!$A$2:$C$801,2,1), "No") -> Yes
A2242: 2241 | B2242: CA-2018-146633 | C2242: 2018-11-15 | D2242: 2018-11-17 | E2242: Second Class | F2242: TG-21310 | G2242: Toby Gnade | H2242: Consumer | I2242: United States | J2242: Los Angeles | K2242: California | L2242: 90049 | M2242: West | N2242: OFF-BI-10002982 | O2242: Office Supplies | P2242: Binders | Q2242: Avery Self-Adhesive Photo Pockets for Polaroid Photos | R2242: 38.136 | S2242: 7 | T2242: 0.2 | U2242: 13.3476 | V2242: =IF(M2242=People!$B$5,People!$A$5,IF(M2242=People!$B$2,People!$A$2,IF(M2242=People!$B$3,People!$A$3,IF(M2242=People!$B$4,People!$A$4,)))) -> Anna Andreadi | W2242: =IFERROR(VLOOKUP(B2242,Returns!$A$2:$C$801,2,1), "No") -> Yes
A2243: 2242 | B2243: US-2018-126893 | C2243: 2018-11-26 | D2243: 2018-12-01 | E2243: Standard Class | F2243: CT-11995 | G2243: Carol Triggs | H2243: Consumer | I2243: United States | J2243: Philadelphia | K2243: Pennsylvania | L2243: 19134 | M2243: East | N2243: TEC-PH-10004165 | O2243: Technology | P2243: Phones | Q2243: Mitel MiVoice 5330e IP Phone | R2243: 494.982 | S2243: 3 | T2243: 0.4 | U2243: -115.4958 | V2243: =IF(M2243=People!$B$5,People!$A$5,IF(M2243=People!$B$2,People!$A$2,IF(M2243=People!$B$3,People!$A$3,IF(M2243=People!$B$4,People!$A$4,)))) -> Chuck Magee | W2243: =IFERROR(VLOOKUP(B2243,Returns!$A$2:$C$801,2,1), "No") -> Yes
A2244: 2243 | B2244: CA-2019-103380 | C2244: 2019-11-21 | D2244: 2019-11-25 | E2244: Standard Class | F2244: BF-11005 | G2244: Barry Franz | H2244: Home Office | I2244: United States | J2244: Pasadena | K2244: California | L2244: 91104 | M2244: West | N2244: OFF-ST-10003442 | O2244: Office Supplies | P2244: Storage | Q2244: Eldon Portable Mobile Manager | R2244: 56.56 | S2244: 2 | T2244: 0 | U2244: 15.2712 | V2244: =IF(M2244=People!$B$5,People!$A$5,IF(M2244=People!$B$2,People!$A$2,IF(M2244=People!$B$3,People!$A$3,IF(M2244=People!$B$4,People!$A$4,)))) -> Anna Andreadi | W2244: =IFERROR(VLOOKUP(B2244,Returns!$A$2:$C$801,2,1), "No") -> Yes
A2245: 2244 | B2245: CA-2019-103380 | C2245: 2019-11-21 | D2245: 2019-11-25 | E2245: Standard Class | F2245: BF-11005 | G2245: Barry Franz | H2245: Home Office | I2245: United States | J2245: Pasadena | K2245: California | L2245: 91104 | M2245: West | N2245: OFF-AR-10003856 | O2245: Office Supplies | P2245: Art | Q2245: Newell 344 | R2245: 5.56 | S2245: 2 | T2245: 0 | U2245: 1.4456 | V2245: =IF(M2245=People!$B$5,People!$A$5,IF(M2245=People!$B$2,People!$A$2,IF(M2245=People!$B$3,People!$A$3,IF(M2245=People!$B$4,People!$A$4,)))) -> Anna Andreadi | W2245: =IFERROR(VLOOKUP(B2245,Returns!$A$2:$C$801,2,1), "No") -> Yes
A2246: 2245 | B2246: CA-2019-103380 | C2246: 2019-11-21 | D2246: 2019-11-25 | E2246: Standard Class | F2246: BF-11005 | G2246: Barry Franz | H2246: Home Office | I2246: United States | J2246: Pasadena | K2246: California | L2246: 91104 | M2246: West | N2246: OFF-FA-10004248 | O2246: Office Supplies | P2246: Fasteners | Q2246: Advantus T-Pin Paper Clips | R2246: 9.02 | S2246: 2 | T2246: 0 | U2246: 3.5178 | V2246: =IF(M2246=People!$B$5,People!$A$5,IF(M2246=People!$B$2,People!$A$2,IF(M2246=People!$B$3,People!$A$3,IF(M2246=People!$B$4,People!$A$4,)))) -> Anna Andreadi | W2246: =IFERROR(VLOOKUP(B2246,Returns!$A$2:$C$801,2,1), "No") -> Yes
A2247: 2246 | B2247: CA-2019-103380 | C2247: 2019-11-21 | D2247: 2019-11-25 | E2247: Standard Class | F2247: BF-11005 | G2247: Barry Franz | H2247: Home Office | I2247: United States | J2247: Pasadena | K2247: California | L2247: 91104 | M2247: West | N2247: OFF-AP-10001492 | O2247: Office Supplies | P2247: Appliances | Q2247: Acco Six-Outlet Power Strip, 4' Cord Length | R2247: 8.62 | S2247: 1 | T2247: 0 | U2247: 2.2412 | V2247: =IF(M2247=People!$B$5,People!$A$5,IF(M2247=People!$B$2,People!$A$2,IF(M2247=People!$B$3,People!$A$3,IF(M2247=People!$B$4,People!$A$4,)))) -> Anna Andreadi | W2247: =IFERROR(VLOOKUP(B2247,Returns!$A$2:$C$801,2,1), "No") -> Yes
A2248: 2247 | B2248: CA-2019-103380 | C2248: 2019-11-21 | D2248: 2019-11-25 | E2248: Standard Class | F2248: BF-11005 | G2248: Barry Franz | H2248: Home Office | I2248: United States | J2248: Pasadena | K2248: California | L2248: 91104 | M2248: West | N2248: TEC-PH-10004165 | O2248: Technology | P2248: Phones | Q2248: Mitel MiVoice 5330e IP Phone | R2248: 659.976 | S2248: 3 | T2248: 0.2 | U2248: 49.4982 | V2248: =IF(M2248=People!$B$5,People!$A$5,IF(M2248=People!$B$2,People!$A$2,IF(M2248=People!$B$3,People!$A$3,IF(M2248=People!$B$4,People!$A$4,)))) -> Anna Andreadi | W2248: =IFERROR(VLOOKUP(B2248,Returns!$A$2:$C$801,2,1), "No") -> Yes
... A5275: 5274 | B5275: US-2018-158309 | C5275: 2018-11-26 | D5275: 2018-11-29 | E5275: First Class | F5275: PA-19060 | G5275: Pete Armstrong | H5275: Home Office | I5275: United States | J5275: Miami | K5275: Florida | L5275: 33142 | M5275: South | N5275: OFF-BI-10000145 | O5275: Office Supplies | P5275: Binders | Q5275: Zipper Ring Binder Pockets | R5275: 3.744 | S5275: 4 | T5275: 0.7 | U5275: -2.6208 | V5275: =IF(M5275=People!$B$5,People!$A$5,IF(M5275=People!$B$2,People!$A$2,IF(M5275=People!$B$3,People!$A$3,IF(M5275=People!$B$4,People!$A$4,)))) -> Cassandra Brandow | W5275: =IFERROR(VLOOKUP(B5275,Returns!$A$2:$C$801,2,1), "No") -> Yes
A5276: 5275 | B5276: CA-2017-162887 | C5276: 2017-11-07 | D5276: 2017-11-09 | E5276: Second Class | F5276: SV-20785 | G5276: Stewart Visinsky | H5276: Consumer | I5276: United States | J5276: Burlington | K5276: Vermont | M5276: East | N5276: FUR-CH-10000595 | O5276: Furniture | P5276: Chairs | Q5276: Safco Contoured Stacking Chairs | R5276: 715.2 | S5276: 3 | T5276: 0 | U5276: 178.8 | V5276: =IF(M5276=People!$B$5,People!$A$5,IF(M5276=People!$B$2,People!$A$2,IF(M5276=People!$B$3,People!$A$3,IF(M5276=People!$B$4,People!$A$4,)))) -> Chuck Magee | W5276: =IFERROR(VLOOKUP(B5276,Returns!$A$2:$C$801,2,1), "No") -> Yes
A5277: 5276 | B5277: CA-2019-147333 | C5277: 2019-12-14 | D5277: 2019-12-20 | E5277: Standard Class | F5277: KL-16555 | G5277: Kelly Lampkin | H5277: Corporate | I5277: United States | J5277: Fayetteville | K5277: Arkansas | L5277: 72701 | M5277: South | N5277: TEC-AC-10004469 | O5277: Technology | P5277: Accessories | Q5277: Microsoft Sculpt Comfort Mouse | R5277: 159.8 | S5277: 4 | T5277: 0 | U5277: 70.312 | V5277: =IF(M5277=People!$B$5,People!$A$5,IF(M5277=People!$B$2,People!$A$2,IF(M5277=People!$B$3,People!$A$3,IF(M5277=People!$B$4,People!$A$4,)))) -> Cassandra Brandow | W5277: =IFERROR(VLOOKUP(B5277,Returns!$A$2:$C$801,2,1), "No") -> Yes
A5278: 5277 | B5278: CA-2019-147333 | C5278: 2019-12-14 | D5278: 2019-12-20 | E5278: Standard Class | F5278: KL-16555 | G5278: Kelly Lampkin | H5278: Corporate | I5278: United States | J5278: Fayetteville | K5278: Arkansas | L5278: 72701 | M5278: South | N5278: TEC-AC-10003038 | O5278: Technology | P5278: Accessories | Q5278: Kingston Digital DataTraveler 16GB USB 2.0 | R5278: 44.75 | S5278: 5 | T5278: 0 | U5278: 8.5025 | V5278: =IF(M5278=People!$B$5,People!$A$5,IF(M5278=People!$B$2,People!$A$2,IF(M5278=People!$B$3,People!$A$3,IF(M5278=People!$B$4,People!$A$4,)))) -> Cassandra Brandow | W5278: =IFERROR(VLOOKUP(B5278,Returns!$A$2:$C$801,2,1), "No") -> Yes
A5279: 5278 | B5279: CA-2016-113859 | C5279: 2016-09-13 | D5279: 2016-09-17 | E5279: Standard Class | F5279: BC-11125 | G5279: Becky Castell | H5279: Home Office | I5279: United States | J5279: Odessa | K5279: Texas | L5279: 79762 | M5279: Central | N5279: FUR-CH-10004698 | O5279: Furniture | P5279: Chairs | Q5279: Padded Folding Chairs, Black, 4/Carton | R5279: 340.116 | S5279: 6 | T5279: 0.3 | U5279: -9.7176 | V5279: =IF(M5279=People!$B$5,People!$A$5,IF(M5279=People!$B$2,People!$A$2,IF(M5279=People!$B$3,People!$A$3,IF(M5279=People!$B$4,People!$A$4,)))) -> Kelly Williams | W5279: =IFERROR(VLOOKUP(B5279,Returns!$A$2:$C$801,2,1), "No") -> Yes
A5280: 5279 | B5280: CA-2016-159681 | C5280: 2016-12-07 | D5280: 2016-12-13 | E5280: Standard Class | F5280: PO-18850 | G5280: Patrick O'Brill | H5280: Consumer | I5280: United States | J5280: Virginia Beach | K5280: Virginia | L5280: 23464 | M5280: South | N5280: OFF-PA-10003641 | O5280: Office Supplies | P5280: Paper | Q5280: Xerox 1909 | R5280: 105.52 | S5280: 4 | T5280: 0 | U5280: 48.5392 | V5280: =IF(M5280=People!$B$5,People!$A$5,IF(M5280=People!$B$2,People!$A$2,IF(M5280=People!$B$3,People!$A$3,IF(M5280=People!$B$4,People!$A$4,)))) -> Cassandra Brandow | W5280: =IFERROR(VLOOKUP(B5280,Returns!$A$2:$C$801,2,1), "No") -> Yes
A5281: 5280 | B5281: US-2019-104094 | C5281: 2019-09-07 | D5281: 2019-09-11 | E5281: Standard Class | F5281: AG-10675 | G5281: Anna Gayman | H5281: Consumer | I5281: United States | J5281: Milwaukee | K5281: Wisconsin | L5281: 53209 | M5281: Central | N5281: TEC-AC-10002134 | O5281: Technology | P5281: Accessories | Q5281: Rosewill 107 Normal Keys USB Wired Standard Keyboard | R5281: 13.48 | S5281: 1 | T5281: 0 | U5281: 1.8872 | V5281: =IF(M5281=People!$B$5,People!$A$5,IF(M5281=People!$B$2,People!$A$2,IF(M5281=People!$B$3,People!$A$3,IF(M5281=People!$B$4,People!$A$4,)))) -> Kelly Williams | W5281: =IFERROR(VLOOKUP(B5281,Returns!$A$2:$C$801,2,1), "No") -> Yes
A5282: 5281 | B5282: CA-2019-152709 | C5282: 2019-10-07 | D5282: 2019-10-12 | E5282: Standard Class | F5282: DB-13210 | G5282: Dean Braden | H5282: Consumer | I5282: United States | J5282: Detroit | K5282: Michigan | L5282: 48234 | M5282: Central | N5282: OFF-ST-10001837 | O5282: Office Supplies | P5282: Storage | Q5282: SAFCO Mobile Desk Side File, Wire Frame | R5282: 85.52 | S5282: 2 | T5282: 0 | U5282: 22.2352 | V5282: =IF(M5282=People!$B$5,People!$A$5,IF(M5282=People!$B$2,People!$A$2,IF(M5282=People!$B$3,People!$A$3,IF(M5282=People!$B$4,People!$A$4,)))) -> Kelly Williams | W5282: =IFERROR(VLOOKUP(B5282,Returns!$A$2:$C$801,2,1), "No") -> Yes
A5283: 5282 | B5283: CA-2017-105158 | C5283: 2017-09-05 | D5283: 2017-09-10 | E5283: Standard Class | F5283: SP-20860 | G5283: Sung Pak | H5283: Corporate | I5283: United States | J5283: Rochester | K5283: Minnesota | L5283: 55901 | M5283: Central | N5283: FUR-FU-10001706 | O5283: Furniture | P5283: Furnishings | Q5283: Longer-Life Soft White Bulbs | R5283: 6.16 | S5283: 2 | T5283: 0 | U5283: 2.9568 | V5283: =IF(M5283=People!$B$5,People!$A$5,IF(M5283=People!$B$2,People!$A$2,IF(M5283=People!$B$3,People!$A$3,IF(M5283=People!$B$4,People!$A$4,)))) -> Kelly Williams | W5283: =IFERROR(VLOOKUP(B5283,Returns!$A$2:$C$801,2,1), "No") -> Yes
A5284: 5283 | B5284: CA-2017-105158 | C5284: 2017-09-05 | D5284: 2017-09-10 | E5284: Standard Class | F5284: SP-20860 | G5284: Sung Pak | H5284: Corporate | I5284: United States | J5284: Rochester | K5284: Minnesota | L5284: 55901 | M5284: Central | N5284: OFF-PA-10001970 | O5284: Office Supplies | P5284: Paper | Q5284: Xerox 1881 | R5284: 36.84 | S5284: 3 | T5284: 0 | U5284: 17.3148 | V5284: =IF(M5284=People!$B$5,People!$A$5,IF(M5284=People!$B$2,People!$A$2,IF(M5284=People!$B$3,People!$A$3,IF(M5284=People!$B$4,People!$A$4,)))) -> Kelly Williams | W5284: =IFERROR(VLOOKUP(B5284,Returns!$A$2:$C$801,2,1), "No") -> Yes
A5285: 5284 | B5285: CA-2016-133424 | C5285: 2016-03-30 | D5285: 2016-04-04 | E5285: Standard Class | F5285: Dl-13600 | G5285: Dorris liebe | H5285: Corporate | I5285: United States | J5285: Seattle | K5285: Washington | L5285: 98105 | M5285: West | N5285: OFF-ST-10002957 | O5285: Office Supplies | P5285: Storage | Q5285: Sterilite Show Offs Storage Containers | R5285: 15.84 | S5285: 3 | T5285: 0 | U5285: 0 | V5285: =IF(M5285=People!$B$5,People!$A$5,IF(M5285=People!$B$2,People!$A$2,IF(M5285=People!$B$3,People!$A$3,IF(M5285=People!$B$4,People!$A$4,)))) -> Anna Andreadi | W5285: =IFERROR(VLOOKUP(B5285,Returns!$A$2:$C$801,2,1), "No") -> Yes
A5286: 5285 | B5286: CA-2016-133424 | C5286: 2016-03-30 | D5286: 2016-04-04 | E5286: Standard Class | F5286: Dl-13600 | G5286: Dorris liebe | H5286: Corporate | I5286: United States | J5286: Seattle | K5286: Washington | L5286: 98105 | M5286: West | N5286: OFF-LA-10002312 | O5286: Office Supplies | P5286: Labels | Q5286: Avery 490 | R5286: 44.4 | S5286: 3 | T5286: 0 | U5286: 22.2 | V5286: =IF(M5286=People!$B$5,People!$A$5,IF(M5286=People!$B$2,People!$A$2,IF(M5286=People!$B$3,People!$A$3,IF(M5286=People!$B$4,People!$A$4,)))) -> Anna Andreadi | W5286: =IFERROR(VLOOKUP(B5286,Returns!$A$2:$C$801,2,1), "No") -> Yes
A5287: 5286 | B5287: CA-2019-105991 | C5287: 2019-05-05 | D5287: 2019-05-06 | E5287: First Class | F5287: LH-17020 | G5287: Lisa Hazard | H5287: Consumer | I5287: United States | J5287: Louisville | K5287: Colorado | L5287: 80027 | M5287: West | N5287: OFF-EN-10002600 | O5287: Office Supplies | P5287: Envelopes | Q5287: Redi-Strip #10 Envelopes, 4 1/8 x 9 1/2 | R5287: 21.24 | S5287: 9 | T5287: 0.2 | U5287: 7.434 | V5287: =IF(M5287=People!$B$5,People!$A$5,IF(M5287=People!$B$2,People!$A$2,IF(M5287=People!$B$3,People!$A$3,IF(M5287=People!$B$4,People!$A$4,)))) -> Anna Andreadi | W5287: =IFERROR(VLOOKUP(B5287,Returns!$A$2:$C$801,2,1), "No") -> Yes
...

Sheet People
A1: Person | B1: Region
A2: Anna Andreadi | B2: West
A3: Chuck Magee | B3: East
A4: Kelly Williams | B4: Central
A5: Cassandra Brandow | B5: South

Sheet Returns
A1: Order ID | B1: Returned
A2: CA-2016-100762 | B2: Yes
A3: CA-2016-100762 | B3: Yes
A4: CA-2016-100762 | B4: Yes
A5: CA-2016-100762 | B5: Yes
A6: CA-2016-100867 | B6: Yes
A7: CA-2016-102652 | B7: Yes
A8: CA-2016-102652 | B8: Yes
A9: CA-2016-102652 | B9: Yes
A10: CA-2016-102652 | B10: Yes
A11: CA-2016-103373 | B11: Yes
A12: CA-2016-103744 | B12: Yes
... A801: US-2019-155999 | B801: Yes
